71
Message sent to Discord successfully.
Message sent to Discord successfully.
Message sent to Discord successfully.
Message sent to Discord successfully.
Message sent to Discord successfully.
Message sent to Discord successfully.
Message sent to Discord successfully.
Message sent to Discord successfully.
Message sent to Discord successfully.
Message sent to Discord successfully.
Message sent to Discord successfully.
Message sent to Discord successfully.
Message sent to Discord successfully.
Message sent to Discord successfully.
Message sent to Discord successfully.
Message sent to Discord successfully.
Message sent to Discord successfully.
Message sent to Discord successfully.
Message sent to Discord successfully.
Message sent to Discord successfully.
Message sent to Discord successfully.
Message sent to Discord successfully.
Message sent to Discord successfully.
Message sent to Discord successfully.
Message sent to Discord successfully.
Message sent to Discord successfully.
Message sent to Discord successfully.
Message sent to Discord successfully.
Message sent to Discord successfully.
Message sent to Discord successfully.
Message sent to Discord successfully.
Message sent to Discord successfully.
Message sent to Discord successfully.
Traceback (most recent call last):
  File "/usr/lib/python3/dist-packages/urllib3/connection.py", line 174, in _new_conn
    conn = connection.create_connection(
           ^^^^^^^^^^^^^^^^^^^^^^^^^^^^^
  File "/usr/lib/python3/dist-packages/urllib3/util/connection.py", line 73, in create_connection
    for res in socket.getaddrinfo(host, port, family, socket.SOCK_STREAM):
               ^^^^^^^^^^^^^^^^^^^^^^^^^^^^^^^^^^^^^^^^^^^^^^^^^^^^^^^^^^
  File "/usr/lib/python3.11/socket.py", line 962, in getaddrinfo
    for res in _socket.getaddrinfo(host, port, family, type, proto, flags):
               ^^^^^^^^^^^^^^^^^^^^^^^^^^^^^^^^^^^^^^^^^^^^^^^^^^^^^^^^^^^
socket.gaierror: [Errno -3] Temporary failure in name resolution

During handling of the above exception, another exception occurred:

Traceback (most recent call last):
  File "/usr/lib/python3/dist-packages/urllib3/connectionpool.py", line 704, in urlopen
    httplib_response = self._make_request(
                       ^^^^^^^^^^^^^^^^^^^
  File "/usr/lib/python3/dist-packages/urllib3/connectionpool.py", line 387, in _make_request
    self._validate_conn(conn)
  File "/usr/lib/python3/dist-packages/urllib3/connectionpool.py", line 1045, in _validate_conn
    conn.connect()
  File "/usr/lib/python3/dist-packages/urllib3/connection.py", line 358, in connect
    self.sock = conn = self._new_conn()
                       ^^^^^^^^^^^^^^^^
  File "/usr/lib/python3/dist-packages/urllib3/connection.py", line 186, in _new_conn
    raise NewConnectionError(
urllib3.exceptions.NewConnectionError: <urllib3.connection.HTTPSConnection object at 0xb5cb5ef0>: Failed to establish a new connection: [Errno -3] Temporary failure in name resolution

During handling of the above exception, another exception occurred:

Traceback (most recent call last):
  File "/usr/lib/python3/dist-packages/requests/adapters.py", line 489, in send
    resp = conn.urlopen(
           ^^^^^^^^^^^^^
  File "/usr/lib/python3/dist-packages/urllib3/connectionpool.py", line 788, in urlopen
    retries = retries.increment(
              ^^^^^^^^^^^^^^^^^^
  File "/usr/lib/python3/dist-packages/urllib3/util/retry.py", line 592, in increment
    raise MaxRetryError(_pool, url, error or ResponseError(cause))
urllib3.exceptions.MaxRetryError: HTTPSConnectionPool(host='discord.com', port=443): Max retries exceeded with url: /api/webhooks/1279839496577220689/3tY_Wdaw5xBo8Z_wxtS3sy7qjCCh1flXQqJRnjFdweItCw3tof1XabOBWu63gA9oZLuq (Caused by NewConnectionError('<urllib3.connection.HTTPSConnection object at 0xb5cb5ef0>: Failed to establish a new connection: [Errno -3] Temporary failure in name resolution'))

During handling of the above exception, another exception occurred:

Traceback (most recent call last):
  File "/home/tomo/Documents/piprojects/main.py", line 12, in <module>
    main()
  File "/home/tomo/Documents/piprojects/main.py", line 10, in main
    aloe.main()
  File "/home/tomo/Documents/piprojects/aloe/main.py", line 9, in main
    discord.send_to_discord(webhooks.aloe, content)
  File "/home/tomo/Documents/piprojects/scripts/discord.py", line 8, in send_to_discord
    response = requests.post(webhook, json=data)
               ^^^^^^^^^^^^^^^^^^^^^^^^^^^^^^^^^
  File "/usr/lib/python3/dist-packages/requests/api.py", line 115, in post
    return request("post", url, data=data, json=json, **kwargs)
           ^^^^^^^^^^^^^^^^^^^^^^^^^^^^^^^^^^^^^^^^^^^^^^^^^^^^
  File "/usr/lib/python3/dist-packages/requests/api.py", line 59, in request
    return session.request(method=method, url=url, **kwargs)
           ^^^^^^^^^^^^^^^^^^^^^^^^^^^^^^^^^^^^^^^^^^^^^^^^^
  File "/usr/lib/python3/dist-packages/requests/sessions.py", line 587, in request
    resp = self.send(prep, **send_kwargs)
           ^^^^^^^^^^^^^^^^^^^^^^^^^^^^^^
  File "/usr/lib/python3/dist-packages/requests/sessions.py", line 701, in send
    r = adapter.send(request, **kwargs)
        ^^^^^^^^^^^^^^^^^^^^^^^^^^^^^^^
  File "/usr/lib/python3/dist-packages/requests/adapters.py", line 565, in send
    raise ConnectionError(e, request=request)
requests.exceptions.ConnectionError: HTTPSConnectionPool(host='discord.com', port=443): Max retries exceeded with url: /api/webhooks/1279839496577220689/3tY_Wdaw5xBo8Z_wxtS3sy7qjCCh1flXQqJRnjFdweItCw3tof1XabOBWu63gA9oZLuq (Caused by NewConnectionError('<urllib3.connection.HTTPSConnection object at 0xb5cb5ef0>: Failed to establish a new connection: [Errno -3] Temporary failure in name resolution'))
